2018-12-20 02:51:49,589 > INFO > Starting Webserver
2019-01-09 05:40:44,334 > INFO > Starting Webserver
2019-01-09 05:41:39,417 > INFO > Starting Webserver
2019-01-11 04:50:12,410 > INFO > Starting Webserver
2019-01-11 04:54:07,736 > INFO > Starting Webserver
2019-01-11 05:23:36,814 > INFO > Starting Webserver
2019-01-14 03:42:37,489 > ERROR > solr admin api failed
Traceback (most recent call last):
  File "/usr/lib/python3/dist-packages/urllib3/connection.py", line 137, in _new_conn
    (self.host, self.port), self.timeout, **extra_kw)
  File "/usr/lib/python3/dist-packages/urllib3/util/connection.py", line 91, in create_connection
    raise err
  File "/usr/lib/python3/dist-packages/urllib3/util/connection.py", line 81, in create_connection
    sock.connect(sa)
ConnectionRefusedError: [Errno 111] Connection refused

During handling of the above exception, another exception occurred:

Traceback (most recent call last):
  File "/usr/lib/python3/dist-packages/urllib3/connectionpool.py", line 560, in urlopen
    body=body, headers=headers)
  File "/usr/lib/python3/dist-packages/urllib3/connectionpool.py", line 354, in _make_request
    conn.request(method, url, **httplib_request_kw)
  File "/usr/lib/python3.5/http/client.py", line 1106, in request
    self._send_request(method, url, body, headers)
  File "/usr/lib/python3.5/http/client.py", line 1151, in _send_request
    self.endheaders(body)
  File "/usr/lib/python3.5/http/client.py", line 1102, in endheaders
    self._send_output(message_body)
  File "/usr/lib/python3.5/http/client.py", line 934, in _send_output
    self.send(msg)
  File "/usr/lib/python3.5/http/client.py", line 877, in send
    self.connect()
  File "/usr/lib/python3/dist-packages/urllib3/connection.py", line 162, in connect
    conn = self._new_conn()
  File "/usr/lib/python3/dist-packages/urllib3/connection.py", line 146, in _new_conn
    self, "Failed to establish a new connection: %s" % e)
requests.packages.urllib3.exceptions.NewConnectionError: <requests.packages.urllib3.connection.HTTPConnection object at 0x7f53e8448048>: Failed to establish a new connection: [Errno 111] Connection refused

During handling of the above exception, another exception occurred:

Traceback (most recent call last):
  File "/usr/lib/python3/dist-packages/requests/adapters.py", line 376, in send
    timeout=timeout
  File "/usr/lib/python3/dist-packages/urllib3/connectionpool.py", line 610, in urlopen
    _stacktrace=sys.exc_info()[2])
  File "/usr/lib/python3/dist-packages/urllib3/util/retry.py", line 273, in increment
    raise MaxRetryError(_pool, url, error or ResponseError(cause))
requests.packages.urllib3.exceptions.MaxRetryError: HTTPConnectionPool(host='127.0.0.1', port=8983): Max retries exceeded with url: /solr/admin/cores?action=CREATE&name=priya_test&instanceDir=priya_test&dataDir=data&configSet=template_ok (Caused by NewConnectionError('<requests.packages.urllib3.connection.HTTPConnection object at 0x7f53e8448048>: Failed to establish a new connection: [Errno 111] Connection refused',))

During handling of the above exception, another exception occurred:

Traceback (most recent call last):
  File "/home/ubuntu/project/search_engine/portal_server/webr_api/__init__.py", line 604, in create_engine
    res = requests.get(url)
  File "/usr/lib/python3/dist-packages/requests/api.py", line 67, in get
    return request('get', url, params=params, **kwargs)
  File "/usr/lib/python3/dist-packages/requests/api.py", line 53, in request
    return session.request(method=method, url=url, **kwargs)
  File "/usr/lib/python3/dist-packages/requests/sessions.py", line 480, in request
    resp = self.send(prep, **send_kwargs)
  File "/usr/lib/python3/dist-packages/requests/sessions.py", line 588, in send
    r = adapter.send(request, **kwargs)
  File "/usr/lib/python3/dist-packages/requests/adapters.py", line 437, in send
    raise ConnectionError(e, request=request)
requests.exceptions.ConnectionError: HTTPConnectionPool(host='127.0.0.1', port=8983): Max retries exceeded with url: /solr/admin/cores?action=CREATE&name=priya_test&instanceDir=priya_test&dataDir=data&configSet=template_ok (Caused by NewConnectionError('<requests.packages.urllib3.connection.HTTPConnection object at 0x7f53e8448048>: Failed to establish a new connection: [Errno 111] Connection refused',))
2019-01-14 04:08:51,886 > INFO > Starting Webserver
2019-01-14 04:09:11,860 > INFO > Starting Webserver
2019-01-30 04:48:23,014 > INFO > Starting Webserver
2019-01-30 04:48:42,592 > INFO > Starting Webserver
2019-02-01 03:03:13,627 > ERROR > domain_update
Traceback (most recent call last):
  File "/home/ubuntu/project/search_engine/portal_server/webr_api/__init__.py", line 718, in domain_update
    form_valid = req_data_validate.validate(req_value, req_validate)
  File "/usr/local/lib/python3.5/dist-packages/cerberus/validator.py", line 868, in validate
    self.__init_processing(document, schema)
  File "/usr/local/lib/python3.5/dist-packages/cerberus/validator.py", line 558, in __init_processing
    errors.DOCUMENT_FORMAT.format(document))
cerberus.validator.DocumentError: '9' is not a document, must be a dict
2019-02-01 03:03:47,102 > ERROR > domain_update
Traceback (most recent call last):
  File "/home/ubuntu/project/search_engine/portal_server/webr_api/__init__.py", line 718, in domain_update
    form_valid = req_data_validate.validate(req_value, req_validate)
  File "/usr/local/lib/python3.5/dist-packages/cerberus/validator.py", line 868, in validate
    self.__init_processing(document, schema)
  File "/usr/local/lib/python3.5/dist-packages/cerberus/validator.py", line 558, in __init_processing
    errors.DOCUMENT_FORMAT.format(document))
cerberus.validator.DocumentError: 'ParallelCrawler' is not a document, must be a dict
2019-02-01 03:32:34,127 > ERROR > domain_update
Traceback (most recent call last):
  File "/home/ubuntu/project/search_engine/portal_server/webr_api/__init__.py", line 718, in domain_update
    form_valid = req_data_validate.validate(req_value, req_validate)
  File "/usr/local/lib/python3.5/dist-packages/cerberus/validator.py", line 868, in validate
    self.__init_processing(document, schema)
  File "/usr/local/lib/python3.5/dist-packages/cerberus/validator.py", line 558, in __init_processing
    errors.DOCUMENT_FORMAT.format(document))
cerberus.validator.DocumentError: '{
        "ParallelCrawler" : 10,
        "Use Sitemaps" : "yes",
        "Allow Robot.txt" : "yes",
        "Use Only Sitemaps" : "no"
    }' is not a document, must be a dict
2019-02-01 03:33:31,560 > ERROR > domain_update
Traceback (most recent call last):
  File "/home/ubuntu/project/search_engine/portal_server/webr_api/__init__.py", line 718, in domain_update
    form_valid = req_data_validate.validate(req_value, req_validate)
  File "/usr/local/lib/python3.5/dist-packages/cerberus/validator.py", line 868, in validate
    self.__init_processing(document, schema)
  File "/usr/local/lib/python3.5/dist-packages/cerberus/validator.py", line 558, in __init_processing
    errors.DOCUMENT_FORMAT.format(document))
cerberus.validator.DocumentError: '[
        "ParallelCrawler" : 10,
        "Use Sitemaps" : "yes",
        "Allow Robot.txt" : "yes",
        "Use Only Sitemaps" : "no"
    ]' is not a document, must be a dict
2019-02-05 15:58:51,888 > INFO > Starting Webserver
2019-02-05 16:00:22,916 > ERROR > domain_update
Traceback (most recent call last):
  File "/home/ubuntu/project/search_engine/portal_server/webr_api/__init__.py", line 786, in domain_update
    query_sntx.get("$set").update({"UpdatedAt":datetime.datetime.utcnow(),"last_updater_ip":str(request.remote_addr)})
AttributeError: 'NoneType' object has no attribute 'update'
2019-02-05 16:03:30,942 > INFO > Starting Webserver
2019-02-05 16:04:47,770 > ERROR > domain_update
Traceback (most recent call last):
  File "/home/ubuntu/project/search_engine/portal_server/webr_api/__init__.py", line 788, in domain_update
    results = engine_collection.update_one({"user_id":user_id,"EngineName":engine_name,"DomainName":domain_name},query_sntx)
  File "/usr/local/lib/python3.5/dist-packages/pymongo/collection.py", line 995, in update_one
    session=session),
  File "/usr/local/lib/python3.5/dist-packages/pymongo/collection.py", line 851, in _update_retryable
    _update, session)
  File "/usr/local/lib/python3.5/dist-packages/pymongo/mongo_client.py", line 1248, in _retryable_write
    return self._retry_with_session(retryable, func, s, None)
  File "/usr/local/lib/python3.5/dist-packages/pymongo/mongo_client.py", line 1201, in _retry_with_session
    return func(session, sock_info, retryable)
  File "/usr/local/lib/python3.5/dist-packages/pymongo/collection.py", line 847, in _update
    retryable_write=retryable_write)
  File "/usr/local/lib/python3.5/dist-packages/pymongo/collection.py", line 818, in _update
    _check_write_command_response(result)
  File "/usr/local/lib/python3.5/dist-packages/pymongo/helpers.py", line 217, in _check_write_command_response
    _raise_last_write_error(write_errors)
  File "/usr/local/lib/python3.5/dist-packages/pymongo/helpers.py", line 199, in _raise_last_write_error
    raise WriteError(error.get("errmsg"), error.get("code"), error)
pymongo.errors.WriteError: $pullAll requires an array argument but was given a object
2019-02-05 16:05:39,395 > ERROR > domain_update
Traceback (most recent call last):
  File "/home/ubuntu/project/search_engine/portal_server/webr_api/__init__.py", line 729, in domain_update
    list_value = json.loads(req_value)
  File "/usr/lib/python3.5/json/__init__.py", line 319, in loads
    return _default_decoder.decode(s)
  File "/usr/lib/python3.5/json/decoder.py", line 339, in decode
    obj, end = self.raw_decode(s, idx=_w(s, 0).end())
  File "/usr/lib/python3.5/json/decoder.py", line 357, in raw_decode
    raise JSONDecodeError("Expecting value", s, err.value) from None
json.decoder.JSONDecodeError: Expecting value: line 1 column 2 (char 1)
2019-02-05 16:09:28,405 > INFO > Starting Webserver
2019-02-05 16:31:09,237 > INFO > Starting Webserver
2019-02-05 16:31:16,529 > ERROR > domain_update_list_query
Traceback (most recent call last):
  File "/home/ubuntu/project/search_engine/portal_server/webr_api/__init__.py", line 653, in domain_update_list_query
    if req_action == 'set':
NameError: name 'req_action' is not defined
2019-02-05 16:33:10,214 > INFO > Starting Webserver
2019-02-05 16:33:16,593 > ERROR > domain_update
Traceback (most recent call last):
  File "/home/ubuntu/project/search_engine/portal_server/webr_api/__init__.py", line 763, in domain_update
    query_sntx.update(created_query)
AttributeError: 'NoneType' object has no attribute 'update'
2019-02-05 16:33:26,526 > ERROR > domain_update
Traceback (most recent call last):
  File "/home/ubuntu/project/search_engine/portal_server/webr_api/__init__.py", line 763, in domain_update
    query_sntx.update(created_query)
AttributeError: 'NoneType' object has no attribute 'update'
2019-02-05 16:34:53,259 > INFO > Starting Webserver
2019-02-05 16:39:38,257 > INFO > Starting Webserver
2019-02-05 16:55:19,483 > INFO > Starting Webserver
2019-02-05 16:56:02,332 > ERROR > domain_update
Traceback (most recent call last):
  File "/home/ubuntu/project/search_engine/portal_server/webr_api/__init__.py", line 774, in domain_update
    engine_collection.update_one({"user_id":user_id,"EngineName":engine_name,"DomainName":domain_name},update_info)
  File "/usr/local/lib/python3.5/dist-packages/pymongo/collection.py", line 985, in update_one
    common.validate_ok_for_update(update)
  File "/usr/local/lib/python3.5/dist-packages/pymongo/common.py", line 494, in validate_ok_for_update
    raise ValueError('update only works with $ operators')
ValueError: update only works with $ operators
2019-02-05 16:56:14,704 > ERROR > domain_update
Traceback (most recent call last):
  File "/home/ubuntu/project/search_engine/portal_server/webr_api/__init__.py", line 774, in domain_update
    engine_collection.update_one({"user_id":user_id,"EngineName":engine_name,"DomainName":domain_name},update_info)
  File "/usr/local/lib/python3.5/dist-packages/pymongo/collection.py", line 985, in update_one
    common.validate_ok_for_update(update)
  File "/usr/local/lib/python3.5/dist-packages/pymongo/common.py", line 494, in validate_ok_for_update
    raise ValueError('update only works with $ operators')
ValueError: update only works with $ operators
2019-02-05 16:58:15,872 > INFO > Starting Webserver
2019-02-10 00:23:06,612 > ERROR > domain_update
Traceback (most recent call last):
  File "/home/ubuntu/project/search_engine/portal_server/webr_api/__init__.py", line 755, in domain_update
    list_value = json.loads(req_value)
  File "/usr/lib/python3.5/json/__init__.py", line 319, in loads
    return _default_decoder.decode(s)
  File "/usr/lib/python3.5/json/decoder.py", line 339, in decode
    obj, end = self.raw_decode(s, idx=_w(s, 0).end())
  File "/usr/lib/python3.5/json/decoder.py", line 357, in raw_decode
    raise JSONDecodeError("Expecting value", s, err.value) from None
json.decoder.JSONDecodeError: Expecting value: line 1 column 1 (char 0)
2019-02-10 00:24:11,834 > ERROR > domain_update
Traceback (most recent call last):
  File "/home/ubuntu/project/search_engine/portal_server/webr_api/__init__.py", line 755, in domain_update
    list_value = json.loads(req_value)
  File "/usr/lib/python3.5/json/__init__.py", line 319, in loads
    return _default_decoder.decode(s)
  File "/usr/lib/python3.5/json/decoder.py", line 339, in decode
    obj, end = self.raw_decode(s, idx=_w(s, 0).end())
  File "/usr/lib/python3.5/json/decoder.py", line 357, in raw_decode
    raise JSONDecodeError("Expecting value", s, err.value) from None
json.decoder.JSONDecodeError: Expecting value: line 1 column 1 (char 0)
2019-02-10 01:33:15,422 > ERROR > domain_update
Traceback (most recent call last):
  File "/home/ubuntu/project/search_engine/portal_server/webr_api/__init__.py", line 744, in domain_update
    form_valid = req_data_validate.validate(req_value, req_validate)
  File "/usr/local/lib/python3.5/dist-packages/cerberus/validator.py", line 868, in validate
    self.__init_processing(document, schema)
  File "/usr/local/lib/python3.5/dist-packages/cerberus/validator.py", line 558, in __init_processing
    errors.DOCUMENT_FORMAT.format(document))
cerberus.validator.DocumentError: '{
        "ParallelCrawler" : 11,
        "Use Sitemaps" : "no",
        "Allow Robot.txt" : "yes",
        "Use Only Sitemaps" : "no"
    }' is not a document, must be a dict
2019-02-10 01:33:33,718 > ERROR > domain_update
Traceback (most recent call last):
  File "/home/ubuntu/project/search_engine/portal_server/webr_api/__init__.py", line 744, in domain_update
    form_valid = req_data_validate.validate(req_value, req_validate)
  File "/usr/local/lib/python3.5/dist-packages/cerberus/validator.py", line 868, in validate
    self.__init_processing(document, schema)
  File "/usr/local/lib/python3.5/dist-packages/cerberus/validator.py", line 558, in __init_processing
    errors.DOCUMENT_FORMAT.format(document))
cerberus.validator.DocumentError: '[
        "ParallelCrawler" : 11,
        "Use Sitemaps" : "no",
        "Allow Robot.txt" : "yes",
        "Use Only Sitemaps" : "no"
    ]' is not a document, must be a dict
2019-02-10 01:33:42,768 > ERROR > domain_update
Traceback (most recent call last):
  File "/home/ubuntu/project/search_engine/portal_server/webr_api/__init__.py", line 744, in domain_update
    form_valid = req_data_validate.validate(req_value, req_validate)
  File "/usr/local/lib/python3.5/dist-packages/cerberus/validator.py", line 868, in validate
    self.__init_processing(document, schema)
  File "/usr/local/lib/python3.5/dist-packages/cerberus/validator.py", line 558, in __init_processing
    errors.DOCUMENT_FORMAT.format(document))
cerberus.validator.DocumentError: '{
        "ParallelCrawler" : 11,
        "Use Sitemaps" : "yes",
        "Allow Robot.txt" : "yes",
        "Use Only Sitemaps" : "no"
    }' is not a document, must be a dict
2019-02-10 01:36:42,765 > ERROR > domain_update
Traceback (most recent call last):
  File "/home/ubuntu/project/search_engine/portal_server/webr_api/__init__.py", line 744, in domain_update
    form_valid = req_data_validate.validate(req_value, req_validate)
  File "/usr/local/lib/python3.5/dist-packages/cerberus/validator.py", line 868, in validate
    self.__init_processing(document, schema)
  File "/usr/local/lib/python3.5/dist-packages/cerberus/validator.py", line 558, in __init_processing
    errors.DOCUMENT_FORMAT.format(document))
cerberus.validator.DocumentError: '{
        "ParallelCrawler" : 11,
        "Use Sitemaps" : "yes",
        "Allow Robot.txt" : "yes",
        "Use Only Sitemaps" : "no"
    }' is not a document, must be a dict
2019-02-10 01:37:58,941 > ERROR > domain_update
Traceback (most recent call last):
  File "/home/ubuntu/project/search_engine/portal_server/webr_api/__init__.py", line 744, in domain_update
    form_valid = req_data_validate.validate(req_value, req_validate)
  File "/usr/local/lib/python3.5/dist-packages/cerberus/validator.py", line 868, in validate
    self.__init_processing(document, schema)
  File "/usr/local/lib/python3.5/dist-packages/cerberus/validator.py", line 558, in __init_processing
    errors.DOCUMENT_FORMAT.format(document))
cerberus.validator.DocumentError: '"AdvancedSettings" : {
        "ParallelCrawler" : 10,
        "Use Sitemaps" : "yes",
        "Allow Robot.txt" : "yes",
        "Use Only Sitemaps" : "no"
    }' is not a document, must be a dict
2019-02-10 01:38:17,103 > ERROR > domain_update
Traceback (most recent call last):
  File "/home/ubuntu/project/search_engine/portal_server/webr_api/__init__.py", line 744, in domain_update
    form_valid = req_data_validate.validate(req_value, req_validate)
  File "/usr/local/lib/python3.5/dist-packages/cerberus/validator.py", line 868, in validate
    self.__init_processing(document, schema)
  File "/usr/local/lib/python3.5/dist-packages/cerberus/validator.py", line 558, in __init_processing
    errors.DOCUMENT_FORMAT.format(document))
cerberus.validator.DocumentError: '["AdvancedSettings" : {
        "ParallelCrawler" : 10,
        "Use Sitemaps" : "yes",
        "Allow Robot.txt" : "yes",
        "Use Only Sitemaps" : "no"
    }]' is not a document, must be a dict
2019-02-10 01:39:01,609 > ERROR > domain_update
Traceback (most recent call last):
  File "/home/ubuntu/project/search_engine/portal_server/webr_api/__init__.py", line 744, in domain_update
    form_valid = req_data_validate.validate(req_value, req_validate)
  File "/usr/local/lib/python3.5/dist-packages/cerberus/validator.py", line 868, in validate
    self.__init_processing(document, schema)
  File "/usr/local/lib/python3.5/dist-packages/cerberus/validator.py", line 558, in __init_processing
    errors.DOCUMENT_FORMAT.format(document))
cerberus.validator.DocumentError: '{"AdvancedSettings" : {
        "ParallelCrawler" : 10,
        "Use Sitemaps" : "yes",
        "Allow Robot.txt" : "yes",
        "Use Only Sitemaps" : "no"
    }}' is not a document, must be a dict
2019-02-11 02:17:02,550 > ERROR > domain_update
Traceback (most recent call last):
  File "/home/ubuntu/project/search_engine/portal_server/webr_api/__init__.py", line 755, in domain_update
    list_value = json.loads(req_value)
  File "/usr/lib/python3.5/json/__init__.py", line 319, in loads
    return _default_decoder.decode(s)
  File "/usr/lib/python3.5/json/decoder.py", line 339, in decode
    obj, end = self.raw_decode(s, idx=_w(s, 0).end())
  File "/usr/lib/python3.5/json/decoder.py", line 355, in raw_decode
    obj, end = self.scan_once(s, idx)
json.decoder.JSONDecodeError: Expecting property name enclosed in double quotes: line 1 column 2 (char 1)
2019-02-11 02:19:04,756 > ERROR > domain_update
Traceback (most recent call last):
  File "/home/ubuntu/project/search_engine/portal_server/webr_api/__init__.py", line 755, in domain_update
    list_value = json.loads(req_value)
  File "/usr/lib/python3.5/json/__init__.py", line 319, in loads
    return _default_decoder.decode(s)
  File "/usr/lib/python3.5/json/decoder.py", line 339, in decode
    obj, end = self.raw_decode(s, idx=_w(s, 0).end())
  File "/usr/lib/python3.5/json/decoder.py", line 355, in raw_decode
    obj, end = self.scan_once(s, idx)
json.decoder.JSONDecodeError: Expecting property name enclosed in double quotes: line 1 column 2 (char 1)
2019-02-13 00:15:30,862 > ERROR > domain_update
Traceback (most recent call last):
  File "/home/ubuntu/project/search_engine/portal_server/webr_api/__init__.py", line 744, in domain_update
    form_valid = req_data_validate.validate(req_value, req_validate)
  File "/usr/local/lib/python3.5/dist-packages/cerberus/validator.py", line 868, in validate
    self.__init_processing(document, schema)
  File "/usr/local/lib/python3.5/dist-packages/cerberus/validator.py", line 558, in __init_processing
    errors.DOCUMENT_FORMAT.format(document))
cerberus.validator.DocumentError: '[{
        "ParallelCrawler" : 10,
        "Use Sitemaps" : "yes",
        "Allow Robot.txt" : "yes",
        "Use Only Sitemaps" : "no"
    }]' is not a document, must be a dict
2019-02-13 00:16:05,836 > ERROR > domain_update
Traceback (most recent call last):
  File "/home/ubuntu/project/search_engine/portal_server/webr_api/__init__.py", line 744, in domain_update
    form_valid = req_data_validate.validate(req_value, req_validate)
  File "/usr/local/lib/python3.5/dist-packages/cerberus/validator.py", line 868, in validate
    self.__init_processing(document, schema)
  File "/usr/local/lib/python3.5/dist-packages/cerberus/validator.py", line 558, in __init_processing
    errors.DOCUMENT_FORMAT.format(document))
cerberus.validator.DocumentError: '{
        "ParallelCrawler" : 10,
        "Use Sitemaps" : "yes",
        "Allow Robot.txt" : "yes",
        "Use Only Sitemaps" : "no"
    }' is not a document, must be a dict
2019-02-13 00:16:13,088 > ERROR > domain_update
Traceback (most recent call last):
  File "/home/ubuntu/project/search_engine/portal_server/webr_api/__init__.py", line 744, in domain_update
    form_valid = req_data_validate.validate(req_value, req_validate)
  File "/usr/local/lib/python3.5/dist-packages/cerberus/validator.py", line 868, in validate
    self.__init_processing(document, schema)
  File "/usr/local/lib/python3.5/dist-packages/cerberus/validator.py", line 558, in __init_processing
    errors.DOCUMENT_FORMAT.format(document))
cerberus.validator.DocumentError: '{
        "ParallelCrawler" : 10,
        "Use Sitemaps" : "yes",
        "Allow Robot.txt" : "yes",
        "Use Only Sitemaps" : "no"
    }' is not a document, must be a dict
2019-02-13 04:00:30,940 > ERROR > domain_update
Traceback (most recent call last):
  File "/home/ubuntu/project/search_engine/portal_server/webr_api/__init__.py", line 755, in domain_update
    list_value = json.loads(req_value)
  File "/usr/lib/python3.5/json/__init__.py", line 319, in loads
    return _default_decoder.decode(s)
  File "/usr/lib/python3.5/json/decoder.py", line 339, in decode
    obj, end = self.raw_decode(s, idx=_w(s, 0).end())
  File "/usr/lib/python3.5/json/decoder.py", line 357, in raw_decode
    raise JSONDecodeError("Expecting value", s, err.value) from None
json.decoder.JSONDecodeError: Expecting value: line 1 column 3 (char 2)
2019-02-13 04:32:28,659 > ERROR > domain_update
Traceback (most recent call last):
  File "/home/ubuntu/project/search_engine/portal_server/webr_api/__init__.py", line 755, in domain_update
    list_value = json.loads(req_value)
  File "/usr/lib/python3.5/json/__init__.py", line 319, in loads
    return _default_decoder.decode(s)
  File "/usr/lib/python3.5/json/decoder.py", line 339, in decode
    obj, end = self.raw_decode(s, idx=_w(s, 0).end())
  File "/usr/lib/python3.5/json/decoder.py", line 357, in raw_decode
    raise JSONDecodeError("Expecting value", s, err.value) from None
json.decoder.JSONDecodeError: Expecting value: line 1 column 3 (char 2)
2019-02-13 04:46:04,719 > ERROR > domain_update
Traceback (most recent call last):
  File "/home/ubuntu/project/search_engine/portal_server/webr_api/__init__.py", line 744, in domain_update
    form_valid = req_data_validate.validate(req_value, req_validate)
  File "/usr/local/lib/python3.5/dist-packages/cerberus/validator.py", line 868, in validate
    self.__init_processing(document, schema)
  File "/usr/local/lib/python3.5/dist-packages/cerberus/validator.py", line 558, in __init_processing
    errors.DOCUMENT_FORMAT.format(document))
cerberus.validator.DocumentError: '{
        "ParallelCrawler" : 10,
        "Use Sitemaps" : "yes",
        "Allow Robot.txt" : "yes",
        "Use Only Sitemaps" : "no"
    }' is not a document, must be a dict
2019-02-13 04:58:26,469 > INFO > Starting Webserver
2019-02-13 23:57:05,114 > ERROR > domain_update
Traceback (most recent call last):
  File "/home/ubuntu/project/search_engine/portal_server/webr_api/__init__.py", line 756, in domain_update
    list_value = json.loads(req_value)
  File "/usr/lib/python3.5/json/__init__.py", line 319, in loads
    return _default_decoder.decode(s)
  File "/usr/lib/python3.5/json/decoder.py", line 339, in decode
    obj, end = self.raw_decode(s, idx=_w(s, 0).end())
  File "/usr/lib/python3.5/json/decoder.py", line 355, in raw_decode
    obj, end = self.scan_once(s, idx)
json.decoder.JSONDecodeError: Expecting property name enclosed in double quotes: line 5 column 9 (char 70)
2019-02-14 00:01:41,692 > ERROR > domain_update
Traceback (most recent call last):
  File "/home/ubuntu/project/search_engine/portal_server/webr_api/__init__.py", line 756, in domain_update
    list_value = json.loads(req_value)
  File "/usr/lib/python3.5/json/__init__.py", line 319, in loads
    return _default_decoder.decode(s)
  File "/usr/lib/python3.5/json/decoder.py", line 339, in decode
    obj, end = self.raw_decode(s, idx=_w(s, 0).end())
  File "/usr/lib/python3.5/json/decoder.py", line 355, in raw_decode
    obj, end = self.scan_once(s, idx)
json.decoder.JSONDecodeError: Expecting property name enclosed in double quotes: line 1 column 3 (char 2)
2019-02-14 00:19:02,723 > ERROR > domain_update
Traceback (most recent call last):
  File "/home/ubuntu/project/search_engine/portal_server/webr_api/__init__.py", line 744, in domain_update
    req_value = json.loads(req_value)
  File "/usr/lib/python3.5/json/__init__.py", line 319, in loads
    return _default_decoder.decode(s)
  File "/usr/lib/python3.5/json/decoder.py", line 342, in decode
    raise JSONDecodeError("Extra data", s, end)
json.decoder.JSONDecodeError: Extra data: line 1 column 20 (char 19)
2019-02-14 00:34:25,077 > ERROR > domain_update
Traceback (most recent call last):
  File "/home/ubuntu/project/search_engine/portal_server/webr_api/__init__.py", line 745, in domain_update
    form_valid = req_data_validate.validate(req_value, req_validate)
  File "/usr/local/lib/python3.5/dist-packages/cerberus/validator.py", line 868, in validate
    self.__init_processing(document, schema)
  File "/usr/local/lib/python3.5/dist-packages/cerberus/validator.py", line 558, in __init_processing
    errors.DOCUMENT_FORMAT.format(document))
cerberus.validator.DocumentError: '[]' is not a document, must be a dict
2019-02-14 00:34:31,873 > ERROR > domain_update
Traceback (most recent call last):
  File "/home/ubuntu/project/search_engine/portal_server/webr_api/__init__.py", line 745, in domain_update
    form_valid = req_data_validate.validate(req_value, req_validate)
  File "/usr/local/lib/python3.5/dist-packages/cerberus/validator.py", line 868, in validate
    self.__init_processing(document, schema)
  File "/usr/local/lib/python3.5/dist-packages/cerberus/validator.py", line 558, in __init_processing
    errors.DOCUMENT_FORMAT.format(document))
cerberus.validator.DocumentError: '[]' is not a document, must be a dict
2019-02-14 00:35:06,939 > ERROR > domain_update
Traceback (most recent call last):
  File "/home/ubuntu/project/search_engine/portal_server/webr_api/__init__.py", line 745, in domain_update
    form_valid = req_data_validate.validate(req_value, req_validate)
  File "/usr/local/lib/python3.5/dist-packages/cerberus/validator.py", line 868, in validate
    self.__init_processing(document, schema)
  File "/usr/local/lib/python3.5/dist-packages/cerberus/validator.py", line 558, in __init_processing
    errors.DOCUMENT_FORMAT.format(document))
cerberus.validator.DocumentError: '[]' is not a document, must be a dict
2019-02-14 00:45:02,793 > ERROR > domain_update
Traceback (most recent call last):
  File "/home/ubuntu/project/search_engine/portal_server/webr_api/__init__.py", line 745, in domain_update
    form_valid = req_data_validate.validate(req_value, req_validate)
  File "/usr/local/lib/python3.5/dist-packages/cerberus/validator.py", line 868, in validate
    self.__init_processing(document, schema)
  File "/usr/local/lib/python3.5/dist-packages/cerberus/validator.py", line 558, in __init_processing
    errors.DOCUMENT_FORMAT.format(document))
cerberus.validator.DocumentError: '[{'weight': 'onlysitemaps', 'field': 'onlysitemaps'}, {'weight': 'sitemaps', 'field': 'sitemaps'}, {'weight': 'robot', 'field': 'robot'}, {'weight': 'parallel', 'field': 'parallel'}]' is not a document, must be a dict
2019-02-14 00:46:52,838 > ERROR > domain_update
Traceback (most recent call last):
  File "/home/ubuntu/project/search_engine/portal_server/webr_api/__init__.py", line 745, in domain_update
    form_valid = req_data_validate.validate(req_value, req_validate)
  File "/usr/local/lib/python3.5/dist-packages/cerberus/validator.py", line 868, in validate
    self.__init_processing(document, schema)
  File "/usr/local/lib/python3.5/dist-packages/cerberus/validator.py", line 558, in __init_processing
    errors.DOCUMENT_FORMAT.format(document))
cerberus.validator.DocumentError: '[{'weight': '', 'field': 'onlysitemaps'}, {'weight': '', 'field': 'sitemaps'}, {'weight': '', 'field': 'robot'}, {'weight': '', 'field': 'parallel'}]' is not a document, must be a dict
2019-02-14 00:48:32,495 > ERROR > domain_update
Traceback (most recent call last):
  File "/home/ubuntu/project/search_engine/portal_server/webr_api/__init__.py", line 745, in domain_update
    form_valid = req_data_validate.validate(req_value, req_validate)
  File "/usr/local/lib/python3.5/dist-packages/cerberus/validator.py", line 868, in validate
    self.__init_processing(document, schema)
  File "/usr/local/lib/python3.5/dist-packages/cerberus/validator.py", line 558, in __init_processing
    errors.DOCUMENT_FORMAT.format(document))
cerberus.validator.DocumentError: '[{'weight': '', 'field': 'onlysitemaps'}, {'weight': '', 'field': 'sitemaps'}, {'weight': '', 'field': 'robot'}, {'weight': '', 'field': 'parallel'}]' is not a document, must be a dict
2019-02-14 00:49:14,817 > ERROR > domain_update
Traceback (most recent call last):
  File "/home/ubuntu/project/search_engine/portal_server/webr_api/__init__.py", line 745, in domain_update
    form_valid = req_data_validate.validate(req_value, req_validate)
  File "/usr/local/lib/python3.5/dist-packages/cerberus/validator.py", line 868, in validate
    self.__init_processing(document, schema)
  File "/usr/local/lib/python3.5/dist-packages/cerberus/validator.py", line 558, in __init_processing
    errors.DOCUMENT_FORMAT.format(document))
cerberus.validator.DocumentError: '[{'weight': '', 'field': 'onlysitemaps'}, {'weight': '', 'field': 'sitemaps'}, {'weight': '', 'field': 'robot'}]' is not a document, must be a dict
2019-02-14 00:49:20,705 > ERROR > domain_update
Traceback (most recent call last):
  File "/home/ubuntu/project/search_engine/portal_server/webr_api/__init__.py", line 745, in domain_update
    form_valid = req_data_validate.validate(req_value, req_validate)
  File "/usr/local/lib/python3.5/dist-packages/cerberus/validator.py", line 868, in validate
    self.__init_processing(document, schema)
  File "/usr/local/lib/python3.5/dist-packages/cerberus/validator.py", line 558, in __init_processing
    errors.DOCUMENT_FORMAT.format(document))
cerberus.validator.DocumentError: '[{'weight': '', 'field': 'onlysitemaps'}, {'weight': '', 'field': 'sitemaps'}, {'weight': '', 'field': 'robot'}]' is not a document, must be a dict
2019-02-14 00:50:55,579 > ERROR > domain_update
Traceback (most recent call last):
  File "/home/ubuntu/project/search_engine/portal_server/webr_api/__init__.py", line 745, in domain_update
    form_valid = req_data_validate.validate(req_value, req_validate)
  File "/usr/local/lib/python3.5/dist-packages/cerberus/validator.py", line 868, in validate
    self.__init_processing(document, schema)
  File "/usr/local/lib/python3.5/dist-packages/cerberus/validator.py", line 558, in __init_processing
    errors.DOCUMENT_FORMAT.format(document))
cerberus.validator.DocumentError: '[{'weight': '', 'field': 'onlysitemaps'}, {'weight': '', 'field': 'sitemaps'}, {'weight': '', 'field': 'robot'}]' is not a document, must be a dict
2019-02-14 00:50:59,026 > ERROR > domain_update
Traceback (most recent call last):
  File "/home/ubuntu/project/search_engine/portal_server/webr_api/__init__.py", line 745, in domain_update
    form_valid = req_data_validate.validate(req_value, req_validate)
  File "/usr/local/lib/python3.5/dist-packages/cerberus/validator.py", line 868, in validate
    self.__init_processing(document, schema)
  File "/usr/local/lib/python3.5/dist-packages/cerberus/validator.py", line 558, in __init_processing
    errors.DOCUMENT_FORMAT.format(document))
cerberus.validator.DocumentError: '[{'weight': '', 'field': 'onlysitemaps'}, {'weight': '', 'field': 'sitemaps'}, {'weight': '', 'field': 'robot'}]' is not a document, must be a dict
2019-02-14 00:51:51,024 > ERROR > domain_update
Traceback (most recent call last):
  File "/home/ubuntu/project/search_engine/portal_server/webr_api/__init__.py", line 745, in domain_update
    form_valid = req_data_validate.validate(req_value, req_validate)
  File "/usr/local/lib/python3.5/dist-packages/cerberus/validator.py", line 868, in validate
    self.__init_processing(document, schema)
  File "/usr/local/lib/python3.5/dist-packages/cerberus/validator.py", line 558, in __init_processing
    errors.DOCUMENT_FORMAT.format(document))
cerberus.validator.DocumentError: '[{'weight': '', 'field': 'onlysitemaps'}, {'weight': '', 'field': 'sitemaps'}, {'weight': '', 'field': 'robot'}]' is not a document, must be a dict
2019-02-14 00:51:54,057 > ERROR > domain_update
Traceback (most recent call last):
  File "/home/ubuntu/project/search_engine/portal_server/webr_api/__init__.py", line 745, in domain_update
    form_valid = req_data_validate.validate(req_value, req_validate)
  File "/usr/local/lib/python3.5/dist-packages/cerberus/validator.py", line 868, in validate
    self.__init_processing(document, schema)
  File "/usr/local/lib/python3.5/dist-packages/cerberus/validator.py", line 558, in __init_processing
    errors.DOCUMENT_FORMAT.format(document))
cerberus.validator.DocumentError: '[{'weight': '', 'field': 'onlysitemaps'}, {'weight': '', 'field': 'sitemaps'}, {'weight': '', 'field': 'robot'}]' is not a document, must be a dict
2019-02-14 00:52:20,662 > ERROR > domain_update
Traceback (most recent call last):
  File "/home/ubuntu/project/search_engine/portal_server/webr_api/__init__.py", line 745, in domain_update
    form_valid = req_data_validate.validate(req_value, req_validate)
  File "/usr/local/lib/python3.5/dist-packages/cerberus/validator.py", line 868, in validate
    self.__init_processing(document, schema)
  File "/usr/local/lib/python3.5/dist-packages/cerberus/validator.py", line 558, in __init_processing
    errors.DOCUMENT_FORMAT.format(document))
cerberus.validator.DocumentError: '[{'weight': '', 'field': 'onlysitemaps'}, {'weight': '', 'field': 'sitemaps'}, {'weight': '', 'field': 'robot'}]' is not a document, must be a dict
2019-02-14 00:52:30,785 > ERROR > domain_update
Traceback (most recent call last):
  File "/home/ubuntu/project/search_engine/portal_server/webr_api/__init__.py", line 745, in domain_update
    form_valid = req_data_validate.validate(req_value, req_validate)
  File "/usr/local/lib/python3.5/dist-packages/cerberus/validator.py", line 868, in validate
    self.__init_processing(document, schema)
  File "/usr/local/lib/python3.5/dist-packages/cerberus/validator.py", line 558, in __init_processing
    errors.DOCUMENT_FORMAT.format(document))
cerberus.validator.DocumentError: '[{'weight': '', 'field': 'onlysitemaps'}, {'weight': '', 'field': 'sitemaps'}, {'weight': '', 'field': 'robot'}]' is not a document, must be a dict
2019-02-14 04:13:33,146 > ERROR > domain_update
Traceback (most recent call last):
  File "/home/ubuntu/project/search_engine/portal_server/webr_api/__init__.py", line 745, in domain_update
    form_valid = req_data_validate.validate(req_value, req_validate)
  File "/usr/local/lib/python3.5/dist-packages/cerberus/validator.py", line 868, in validate
    self.__init_processing(document, schema)
  File "/usr/local/lib/python3.5/dist-packages/cerberus/validator.py", line 558, in __init_processing
    errors.DOCUMENT_FORMAT.format(document))
cerberus.validator.DocumentError: '[{'weight': '', 'field': 'onlysitemaps'}, {'weight': '', 'field': 'sitemaps'}, {'weight': '', 'field': 'robot'}]' is not a document, must be a dict
2019-02-14 04:14:10,970 > ERROR > domain_update
Traceback (most recent call last):
  File "/home/ubuntu/project/search_engine/portal_server/webr_api/__init__.py", line 745, in domain_update
    form_valid = req_data_validate.validate(req_value, req_validate)
  File "/usr/local/lib/python3.5/dist-packages/cerberus/validator.py", line 868, in validate
    self.__init_processing(document, schema)
  File "/usr/local/lib/python3.5/dist-packages/cerberus/validator.py", line 558, in __init_processing
    errors.DOCUMENT_FORMAT.format(document))
cerberus.validator.DocumentError: '[{'weight': '', 'field': 'onlysitemaps'}, {'weight': '', 'field': 'sitemaps'}, {'weight': '', 'field': 'robot'}]' is not a document, must be a dict
2019-02-14 04:18:29,793 > ERROR > domain_update
Traceback (most recent call last):
  File "/home/ubuntu/project/search_engine/portal_server/webr_api/__init__.py", line 745, in domain_update
    form_valid = req_data_validate.validate(req_value, req_validate)
  File "/usr/local/lib/python3.5/dist-packages/cerberus/validator.py", line 868, in validate
    self.__init_processing(document, schema)
  File "/usr/local/lib/python3.5/dist-packages/cerberus/validator.py", line 558, in __init_processing
    errors.DOCUMENT_FORMAT.format(document))
cerberus.validator.DocumentError: '[{'weight': '', 'field': 'onlysitemaps'}, {'weight': '', 'field': 'sitemaps'}, {'weight': '', 'field': 'robot'}, {'weight': 'parallel', 'field': 'parallel'}]' is not a document, must be a dict
2019-02-14 04:30:27,994 > ERROR > domain_update
Traceback (most recent call last):
  File "/home/ubuntu/project/search_engine/portal_server/webr_api/__init__.py", line 745, in domain_update
    form_valid = req_data_validate.validate(req_value, req_validate)
  File "/usr/local/lib/python3.5/dist-packages/cerberus/validator.py", line 868, in validate
    self.__init_processing(document, schema)
  File "/usr/local/lib/python3.5/dist-packages/cerberus/validator.py", line 558, in __init_processing
    errors.DOCUMENT_FORMAT.format(document))
cerberus.validator.DocumentError: '[{'Use Only Sitemaps': 'no'}, {'Use Sitemaps': 'no'}, {'Allow Robot.txt': 'yes'}, {'ParallelCrawler': 10}]' is not a document, must be a dict
2019-02-14 04:33:21,052 > ERROR > domain_update
Traceback (most recent call last):
  File "/home/ubuntu/project/search_engine/portal_server/webr_api/__init__.py", line 745, in domain_update
    form_valid = req_data_validate.validate(req_value, req_validate)
  File "/usr/local/lib/python3.5/dist-packages/cerberus/validator.py", line 868, in validate
    self.__init_processing(document, schema)
  File "/usr/local/lib/python3.5/dist-packages/cerberus/validator.py", line 558, in __init_processing
    errors.DOCUMENT_FORMAT.format(document))
cerberus.validator.DocumentError: '[]' is not a document, must be a dict
2019-02-14 04:40:42,209 > ERROR > domain_update
Traceback (most recent call last):
  File "/home/ubuntu/project/search_engine/portal_server/webr_api/__init__.py", line 744, in domain_update
    req_value = json.loads(req_value)
  File "/usr/lib/python3.5/json/__init__.py", line 319, in loads
    return _default_decoder.decode(s)
  File "/usr/lib/python3.5/json/decoder.py", line 339, in decode
    obj, end = self.raw_decode(s, idx=_w(s, 0).end())
  File "/usr/lib/python3.5/json/decoder.py", line 355, in raw_decode
    obj, end = self.scan_once(s, idx)
json.decoder.JSONDecodeError: Expecting property name enclosed in double quotes: line 1 column 2 (char 1)
2019-02-14 04:41:25,574 > ERROR > domain_update
Traceback (most recent call last):
  File "/home/ubuntu/project/search_engine/portal_server/webr_api/__init__.py", line 744, in domain_update
    req_value = json.loads(req_value)
  File "/usr/lib/python3.5/json/__init__.py", line 319, in loads
    return _default_decoder.decode(s)
  File "/usr/lib/python3.5/json/decoder.py", line 339, in decode
    obj, end = self.raw_decode(s, idx=_w(s, 0).end())
  File "/usr/lib/python3.5/json/decoder.py", line 355, in raw_decode
    obj, end = self.scan_once(s, idx)
json.decoder.JSONDecodeError: Expecting property name enclosed in double quotes: line 1 column 2 (char 1)
2019-02-14 04:41:55,002 > ERROR > domain_update
Traceback (most recent call last):
  File "/home/ubuntu/project/search_engine/portal_server/webr_api/__init__.py", line 744, in domain_update
    req_value = json.loads(req_value)
  File "/usr/lib/python3.5/json/__init__.py", line 319, in loads
    return _default_decoder.decode(s)
  File "/usr/lib/python3.5/json/decoder.py", line 339, in decode
    obj, end = self.raw_decode(s, idx=_w(s, 0).end())
  File "/usr/lib/python3.5/json/decoder.py", line 355, in raw_decode
    obj, end = self.scan_once(s, idx)
json.decoder.JSONDecodeError: Expecting property name enclosed in double quotes: line 1 column 2 (char 1)
2019-02-14 04:42:41,554 > ERROR > domain_update
Traceback (most recent call last):
  File "/home/ubuntu/project/search_engine/portal_server/webr_api/__init__.py", line 744, in domain_update
    req_value = json.loads(req_value)
  File "/usr/lib/python3.5/json/__init__.py", line 319, in loads
    return _default_decoder.decode(s)
  File "/usr/lib/python3.5/json/decoder.py", line 339, in decode
    obj, end = self.raw_decode(s, idx=_w(s, 0).end())
  File "/usr/lib/python3.5/json/decoder.py", line 355, in raw_decode
    obj, end = self.scan_once(s, idx)
json.decoder.JSONDecodeError: Expecting property name enclosed in double quotes: line 1 column 2 (char 1)
2019-02-14 04:43:38,597 > ERROR > domain_update
Traceback (most recent call last):
  File "/home/ubuntu/project/search_engine/portal_server/webr_api/__init__.py", line 749, in domain_update
    error_status.update(req_validate.errors)
AttributeError: 'dict' object has no attribute 'errors'
2019-02-14 04:43:46,184 > ERROR > domain_update
Traceback (most recent call last):
  File "/home/ubuntu/project/search_engine/portal_server/webr_api/__init__.py", line 749, in domain_update
    error_status.update(req_validate.errors)
AttributeError: 'dict' object has no attribute 'errors'
2019-02-14 17:11:50,524 > INFO > Starting Webserver
2019-02-19 03:45:11,275 > ERROR > domain_update
Traceback (most recent call last):
  File "/home/ubuntu/project/search_engine/portal_server/webr_api/__init__.py", line 760, in domain_update
    list_value = json.loads(req_value)
  File "/usr/lib/python3.5/json/__init__.py", line 319, in loads
    return _default_decoder.decode(s)
  File "/usr/lib/python3.5/json/decoder.py", line 339, in decode
    obj, end = self.raw_decode(s, idx=_w(s, 0).end())
  File "/usr/lib/python3.5/json/decoder.py", line 355, in raw_decode
    obj, end = self.scan_once(s, idx)
json.decoder.JSONDecodeError: Expecting ',' delimiter: line 1 column 9 (char 8)
2019-03-11 04:17:00,104 > INFO > Starting Webserver
2019-03-11 05:12:47,471 > INFO > Starting Webserver
2019-03-11 05:16:00,521 > ERROR > domain_update
Traceback (most recent call last):
  File "/home/ubuntu/project/search_engine/portal_server/webr_api/__init__.py", line 757, in domain_update
    list_value = json.loads(req_value)
  File "/usr/lib/python3.5/json/__init__.py", line 319, in loads
    return _default_decoder.decode(s)
  File "/usr/lib/python3.5/json/decoder.py", line 342, in decode
    raise JSONDecodeError("Extra data", s, end)
json.decoder.JSONDecodeError: Extra data: line 4 column 10 (char 67)
2019-03-11 05:18:18,917 > ERROR > domain_update
Traceback (most recent call last):
  File "/home/ubuntu/project/search_engine/portal_server/webr_api/__init__.py", line 757, in domain_update
    list_value = json.loads(req_value)
  File "/usr/lib/python3.5/json/__init__.py", line 319, in loads
    return _default_decoder.decode(s)
  File "/usr/lib/python3.5/json/decoder.py", line 339, in decode
    obj, end = self.raw_decode(s, idx=_w(s, 0).end())
  File "/usr/lib/python3.5/json/decoder.py", line 357, in raw_decode
    raise JSONDecodeError("Expecting value", s, err.value) from None
json.decoder.JSONDecodeError: Expecting value: line 1 column 1 (char 0)
2019-03-11 05:19:36,399 > ERROR > update_key_to_redis_server
Traceback (most recent call last):
  File "/home/ubuntu/project/search_engine/portal_server/webr_api/__init__.py", line 1318, in update_key_to_redis_server
    users.append({"EngineName":engine_name,"DomainName":domain_name})
AttributeError: 'dict' object has no attribute 'append'
2019-03-11 05:21:46,057 > INFO > Starting Webserver
2019-03-14 05:10:33,323 > INFO > Starting Webserver
2019-03-14 05:11:25,355 > INFO > Starting Webserver
2019-03-14 05:12:50,810 > INFO > Starting Webserver
2019-03-14 05:13:33,486 > INFO > Starting Webserver
2019-03-14 05:14:55,399 > INFO > Starting Webserver
2019-03-14 05:18:29,308 > INFO > Starting Webserver
2019-03-19 15:03:45,595 > INFO > Starting Webserver
2019-03-19 15:04:33,822 > WARNING > q=Citizens&key=70726979619fb01e060116da92fd291f430f22e938d28ef934&hl=true&hl.snippets=1&hl.fragsize=100&hl.fl=body
2019-03-19 15:04:33,824 > ERROR > getting elevator from redis failed:
Traceback (most recent call last):
  File "/home/ubuntu/project/search_engine/portal_server/webr_api/__init__.py", line 91, in search_query
    elvate_key = elevate_+user_id+"_"+engine_name+"_"+domain_name
NameError: name 'elevate_' is not defined
2019-03-19 15:06:05,835 > INFO > Starting Webserver
2019-03-19 15:06:15,012 > WARNING > q=Citizens&key=70726979619fb01e060116da92fd291f430f22e938d28ef934&hl=true&hl.snippets=1&hl.fragsize=100&hl.fl=body
2019-03-19 15:06:15,014 > ERROR > search_query
Traceback (most recent call last):
  File "/home/ubuntu/project/search_engine/portal_server/webr_api/__init__.py", line 118, in search_query
    query = query+elevate
TypeError: Can't convert 'NoneType' object to str implicitly
2019-03-19 15:13:23,195 > INFO > Starting Webserver
2019-03-19 15:13:29,987 > WARNING > q=Citizens&key=70726979619fb01e060116da92fd291f430f22e938d28ef934&hl=true&hl.snippets=1&hl.fragsize=100&hl.fl=body
2019-03-19 17:22:36,885 > INFO > Starting Webserver
2019-03-19 17:24:44,694 > INFO > Starting Webserver
2019-03-19 17:26:10,777 > INFO > Starting Webserver
2019-03-19 17:28:27,140 > INFO > Starting Webserver
2019-03-19 17:31:09,703 > INFO > Starting Webserver
2019-03-19 17:33:34,713 > INFO > Starting Webserver
2019-03-19 17:39:58,134 > INFO > Starting Webserver
2019-03-19 17:42:34,074 > WARNING > q=chennai&key=70726979619fb01e060116da92fd291f430f22e938d28ef934&hl=true&hl.snippets=1&hl.fragsize=100&hl.fl=body
2019-03-19 17:47:06,664 > INFO > Starting Webserver
2019-03-19 17:47:13,463 > WARNING > q=chennai&hl=true&hl.snippets=1&hl.fragsize=100&hl.fl=body&fl=title,url,id&qf=title&qf=body&qf=url&bq=title^5,body^1,url^2&defType=dismax
2019-03-19 17:49:24,617 > INFO > Starting Webserver
2019-03-19 17:49:31,037 > WARNING > elevate_priya_wisky_https://gic.delaware.gov
2019-03-19 17:49:31,038 > WARNING > chennai
2019-03-19 17:49:31,038 > WARNING > q=chennai&hl=true&hl.snippets=1&hl.fragsize=100&hl.fl=body&fl=title,url,id&qf=title&qf=body&qf=url&bq=title^5,body^1,url^2&defType=dismax
2019-03-19 17:52:52,218 > WARNING > elevate_priya_wisky_https://gic.delaware.gov
2019-03-19 17:52:52,218 > WARNING > chennai
2019-03-19 17:52:52,219 > WARNING > q=chennai&hl=true&hl.snippets=1&hl.fragsize=100&hl.fl=body&fl=title,url,id&qf=title&qf=body&qf=url&bq=title^5,body^1,url^2&defType=dismax&elevateIds=3cd18d01-e04a-468e-8e04-39f3be8690f1,dfc83116-5c48-4aea-b12a-a2e9f157d979,e38204c2-4557-4fab-b0da-7204dc9da1f4
2019-03-19 17:54:03,551 > WARNING > elevate_priya_wisky_https://gic.delaware.gov
2019-03-19 17:54:03,551 > WARNING > chennai
2019-03-19 17:54:03,551 > WARNING > q=chennai&hl=true&hl.snippets=1&hl.fragsize=100&hl.fl=body&fl=title,url,id&qf=title&qf=body&qf=url&bq=title^5,body^1,url^2&defType=dismax&elevateIds=3cd18d01-e04a-468e-8e04-39f3be8690f1,dfc83116-5c48-4aea-b12a-a2e9f157d979,e38204c2-4557-4fab-b0da-7204dc9da1f4
2019-03-19 17:54:04,811 > WARNING > elevate_priya_wisky_https://gic.delaware.gov
2019-03-19 17:54:04,811 > WARNING > chennai
2019-03-19 17:54:04,811 > WARNING > q=chennai&hl=true&hl.snippets=1&hl.fragsize=100&hl.fl=body&fl=title,url,id&qf=title&qf=body&qf=url&bq=title^5,body^1,url^2&defType=dismax&elevateIds=3cd18d01-e04a-468e-8e04-39f3be8690f1,dfc83116-5c48-4aea-b12a-a2e9f157d979,e38204c2-4557-4fab-b0da-7204dc9da1f4
2019-03-19 17:54:05,844 > WARNING > elevate_priya_wisky_https://gic.delaware.gov
2019-03-19 17:54:05,844 > WARNING > chennai
2019-03-19 17:54:05,845 > WARNING > q=chennai&hl=true&hl.snippets=1&hl.fragsize=100&hl.fl=body&fl=title,url,id&qf=title&qf=body&qf=url&bq=title^5,body^1,url^2&defType=dismax&elevateIds=3cd18d01-e04a-468e-8e04-39f3be8690f1,dfc83116-5c48-4aea-b12a-a2e9f157d979,e38204c2-4557-4fab-b0da-7204dc9da1f4
2019-03-19 17:54:06,774 > WARNING > elevate_priya_wisky_https://gic.delaware.gov
2019-03-19 17:54:06,774 > WARNING > chennai
2019-03-19 17:54:06,774 > WARNING > q=chennai&hl=true&hl.snippets=1&hl.fragsize=100&hl.fl=body&fl=title,url,id&qf=title&qf=body&qf=url&bq=title^5,body^1,url^2&defType=dismax&elevateIds=3cd18d01-e04a-468e-8e04-39f3be8690f1,dfc83116-5c48-4aea-b12a-a2e9f157d979,e38204c2-4557-4fab-b0da-7204dc9da1f4
2019-03-19 17:54:07,749 > WARNING > elevate_priya_wisky_https://gic.delaware.gov
2019-03-19 17:54:07,749 > WARNING > chennai
2019-03-19 17:54:07,749 > WARNING > q=chennai&hl=true&hl.snippets=1&hl.fragsize=100&hl.fl=body&fl=title,url,id&qf=title&qf=body&qf=url&bq=title^5,body^1,url^2&defType=dismax&elevateIds=3cd18d01-e04a-468e-8e04-39f3be8690f1,dfc83116-5c48-4aea-b12a-a2e9f157d979,e38204c2-4557-4fab-b0da-7204dc9da1f4
2019-03-19 17:54:08,592 > WARNING > elevate_priya_wisky_https://gic.delaware.gov
2019-03-19 17:54:08,592 > WARNING > chennai
2019-03-19 17:54:08,593 > WARNING > q=chennai&hl=true&hl.snippets=1&hl.fragsize=100&hl.fl=body&fl=title,url,id&qf=title&qf=body&qf=url&bq=title^5,body^1,url^2&defType=dismax&elevateIds=3cd18d01-e04a-468e-8e04-39f3be8690f1,dfc83116-5c48-4aea-b12a-a2e9f157d979,e38204c2-4557-4fab-b0da-7204dc9da1f4
2019-03-19 17:54:10,412 > WARNING > elevate_priya_wisky_https://gic.delaware.gov
2019-03-19 17:54:10,412 > WARNING > chennai
2019-03-19 17:54:10,413 > WARNING > q=chennai&hl=true&hl.snippets=1&hl.fragsize=100&hl.fl=body&fl=title,url,id&qf=title&qf=body&qf=url&bq=title^5,body^1,url^2&defType=dismax&elevateIds=3cd18d01-e04a-468e-8e04-39f3be8690f1,dfc83116-5c48-4aea-b12a-a2e9f157d979,e38204c2-4557-4fab-b0da-7204dc9da1f4
2019-03-19 17:54:11,414 > WARNING > elevate_priya_wisky_https://gic.delaware.gov
2019-03-19 17:54:11,414 > WARNING > chennai
2019-03-19 17:54:11,414 > WARNING > q=chennai&hl=true&hl.snippets=1&hl.fragsize=100&hl.fl=body&fl=title,url,id&qf=title&qf=body&qf=url&bq=title^5,body^1,url^2&defType=dismax&elevateIds=3cd18d01-e04a-468e-8e04-39f3be8690f1,dfc83116-5c48-4aea-b12a-a2e9f157d979,e38204c2-4557-4fab-b0da-7204dc9da1f4
2019-03-19 17:54:12,270 > WARNING > elevate_priya_wisky_https://gic.delaware.gov
2019-03-19 17:54:12,270 > WARNING > chennai
2019-03-19 17:54:12,270 > WARNING > q=chennai&hl=true&hl.snippets=1&hl.fragsize=100&hl.fl=body&fl=title,url,id&qf=title&qf=body&qf=url&bq=title^5,body^1,url^2&defType=dismax&elevateIds=3cd18d01-e04a-468e-8e04-39f3be8690f1,dfc83116-5c48-4aea-b12a-a2e9f157d979,e38204c2-4557-4fab-b0da-7204dc9da1f4
2019-03-19 17:54:14,004 > WARNING > elevate_priya_wisky_https://gic.delaware.gov
2019-03-19 17:54:14,005 > WARNING > chennai
2019-03-19 17:54:14,005 > WARNING > q=chennai&hl=true&hl.snippets=1&hl.fragsize=100&hl.fl=body&fl=title,url,id&qf=title&qf=body&qf=url&bq=title^5,body^1,url^2&defType=dismax&elevateIds=3cd18d01-e04a-468e-8e04-39f3be8690f1,dfc83116-5c48-4aea-b12a-a2e9f157d979,e38204c2-4557-4fab-b0da-7204dc9da1f4
2019-03-19 17:54:14,947 > WARNING > elevate_priya_wisky_https://gic.delaware.gov
2019-03-19 17:54:14,947 > WARNING > chennai
2019-03-19 17:54:14,947 > WARNING > q=chennai&hl=true&hl.snippets=1&hl.fragsize=100&hl.fl=body&fl=title,url,id&qf=title&qf=body&qf=url&bq=title^5,body^1,url^2&defType=dismax&elevateIds=3cd18d01-e04a-468e-8e04-39f3be8690f1,dfc83116-5c48-4aea-b12a-a2e9f157d979,e38204c2-4557-4fab-b0da-7204dc9da1f4
2019-03-19 17:54:15,842 > WARNING > elevate_priya_wisky_https://gic.delaware.gov
2019-03-19 17:54:15,842 > WARNING > chennai
2019-03-19 17:54:15,843 > WARNING > q=chennai&hl=true&hl.snippets=1&hl.fragsize=100&hl.fl=body&fl=title,url,id&qf=title&qf=body&qf=url&bq=title^5,body^1,url^2&defType=dismax&elevateIds=3cd18d01-e04a-468e-8e04-39f3be8690f1,dfc83116-5c48-4aea-b12a-a2e9f157d979,e38204c2-4557-4fab-b0da-7204dc9da1f4
2019-03-19 17:54:16,795 > WARNING > elevate_priya_wisky_https://gic.delaware.gov
2019-03-19 17:54:16,795 > WARNING > chennai
2019-03-19 17:54:16,796 > WARNING > q=chennai&hl=true&hl.snippets=1&hl.fragsize=100&hl.fl=body&fl=title,url,id&qf=title&qf=body&qf=url&bq=title^5,body^1,url^2&defType=dismax&elevateIds=3cd18d01-e04a-468e-8e04-39f3be8690f1,dfc83116-5c48-4aea-b12a-a2e9f157d979,e38204c2-4557-4fab-b0da-7204dc9da1f4
2019-03-19 17:54:17,943 > WARNING > elevate_priya_wisky_https://gic.delaware.gov
2019-03-19 17:54:17,944 > WARNING > chennai
2019-03-19 17:54:17,944 > WARNING > q=chennai&hl=true&hl.snippets=1&hl.fragsize=100&hl.fl=body&fl=title,url,id&qf=title&qf=body&qf=url&bq=title^5,body^1,url^2&defType=dismax&elevateIds=3cd18d01-e04a-468e-8e04-39f3be8690f1,dfc83116-5c48-4aea-b12a-a2e9f157d979,e38204c2-4557-4fab-b0da-7204dc9da1f4
2019-03-19 17:54:18,889 > WARNING > elevate_priya_wisky_https://gic.delaware.gov
2019-03-19 17:54:18,889 > WARNING > chennai
2019-03-19 17:54:18,889 > WARNING > q=chennai&hl=true&hl.snippets=1&hl.fragsize=100&hl.fl=body&fl=title,url,id&qf=title&qf=body&qf=url&bq=title^5,body^1,url^2&defType=dismax&elevateIds=3cd18d01-e04a-468e-8e04-39f3be8690f1,dfc83116-5c48-4aea-b12a-a2e9f157d979,e38204c2-4557-4fab-b0da-7204dc9da1f4
2019-03-19 17:54:20,164 > WARNING > elevate_priya_wisky_https://gic.delaware.gov
2019-03-19 17:54:20,164 > WARNING > chennai
2019-03-19 17:54:20,164 > WARNING > q=chennai&hl=true&hl.snippets=1&hl.fragsize=100&hl.fl=body&fl=title,url,id&qf=title&qf=body&qf=url&bq=title^5,body^1,url^2&defType=dismax&elevateIds=3cd18d01-e04a-468e-8e04-39f3be8690f1,dfc83116-5c48-4aea-b12a-a2e9f157d979,e38204c2-4557-4fab-b0da-7204dc9da1f4
2019-03-19 17:54:21,060 > WARNING > elevate_priya_wisky_https://gic.delaware.gov
2019-03-19 17:54:21,060 > WARNING > chennai
2019-03-19 17:54:21,061 > WARNING > q=chennai&hl=true&hl.snippets=1&hl.fragsize=100&hl.fl=body&fl=title,url,id&qf=title&qf=body&qf=url&bq=title^5,body^1,url^2&defType=dismax&elevateIds=3cd18d01-e04a-468e-8e04-39f3be8690f1,dfc83116-5c48-4aea-b12a-a2e9f157d979,e38204c2-4557-4fab-b0da-7204dc9da1f4
2019-03-19 17:54:21,877 > WARNING > elevate_priya_wisky_https://gic.delaware.gov
2019-03-19 17:54:21,877 > WARNING > chennai
2019-03-19 17:54:21,877 > WARNING > q=chennai&hl=true&hl.snippets=1&hl.fragsize=100&hl.fl=body&fl=title,url,id&qf=title&qf=body&qf=url&bq=title^5,body^1,url^2&defType=dismax&elevateIds=3cd18d01-e04a-468e-8e04-39f3be8690f1,dfc83116-5c48-4aea-b12a-a2e9f157d979,e38204c2-4557-4fab-b0da-7204dc9da1f4
2019-03-19 17:54:22,696 > WARNING > elevate_priya_wisky_https://gic.delaware.gov
2019-03-19 17:54:22,696 > WARNING > chennai
2019-03-19 17:54:22,696 > WARNING > q=chennai&hl=true&hl.snippets=1&hl.fragsize=100&hl.fl=body&fl=title,url,id&qf=title&qf=body&qf=url&bq=title^5,body^1,url^2&defType=dismax&elevateIds=3cd18d01-e04a-468e-8e04-39f3be8690f1,dfc83116-5c48-4aea-b12a-a2e9f157d979,e38204c2-4557-4fab-b0da-7204dc9da1f4
2019-03-19 17:54:24,297 > WARNING > elevate_priya_wisky_https://gic.delaware.gov
2019-03-19 17:54:24,298 > WARNING > chennai
2019-03-19 17:54:24,298 > WARNING > q=chennai&hl=true&hl.snippets=1&hl.fragsize=100&hl.fl=body&fl=title,url,id&qf=title&qf=body&qf=url&bq=title^5,body^1,url^2&defType=dismax&elevateIds=3cd18d01-e04a-468e-8e04-39f3be8690f1,dfc83116-5c48-4aea-b12a-a2e9f157d979,e38204c2-4557-4fab-b0da-7204dc9da1f4
2019-03-19 18:01:37,393 > INFO > Starting Webserver
2019-03-19 18:23:16,637 > INFO > Starting Webserver
2019-03-19 18:24:43,743 > INFO > Starting Webserver
2019-03-19 18:24:57,693 > ERROR > error
2019-03-19 18:26:05,575 > INFO > Starting Webserver
2019-03-19 18:26:11,789 > ERROR > error
Traceback (most recent call last):
  File "/home/ubuntu/project/search_engine/portal_server/webr_api/__init__.py", line 306, in result_rerank
    t_cursor = int(result.get("cursor"))
TypeError: int() argument must be a string, a bytes-like object or a number, not 'NoneType'
2019-03-19 18:27:52,539 > ERROR > error
Traceback (most recent call last):
  File "/home/ubuntu/project/search_engine/portal_server/webr_api/__init__.py", line 307, in result_rerank
    t_count = int(result.get("count"))
TypeError: int() argument must be a string, a bytes-like object or a number, not 'NoneType'
2019-03-19 18:28:15,827 > ERROR > result_rerank
Traceback (most recent call last):
  File "/home/ubuntu/project/search_engine/portal_server/webr_api/__init__.py", line 266, in result_rerank
    key = "elevate_"+user_id+"_"+engine_name+"_"+domain_name
TypeError: Can't convert 'NoneType' object to str implicitly
2019-03-19 18:32:08,496 > INFO > Starting Webserver
2019-03-19 18:49:21,513 > INFO > Starting Webserver
