2018-12-20 02:51:49,589 > INFO > Starting Webserver
2019-01-09 05:40:44,334 > INFO > Starting Webserver
2019-01-09 05:41:39,417 > INFO > Starting Webserver
2019-01-11 04:50:12,410 > INFO > Starting Webserver
2019-01-11 04:54:07,736 > INFO > Starting Webserver
2019-01-11 05:23:36,814 > INFO > Starting Webserver
2019-01-14 03:42:37,489 > ERROR > solr admin api failed
Traceback (most recent call last):
  File "/usr/lib/python3/dist-packages/urllib3/connection.py", line 137, in _new_conn
    (self.host, self.port), self.timeout, **extra_kw)
  File "/usr/lib/python3/dist-packages/urllib3/util/connection.py", line 91, in create_connection
    raise err
  File "/usr/lib/python3/dist-packages/urllib3/util/connection.py", line 81, in create_connection
    sock.connect(sa)
ConnectionRefusedError: [Errno 111] Connection refused

During handling of the above exception, another exception occurred:

Traceback (most recent call last):
  File "/usr/lib/python3/dist-packages/urllib3/connectionpool.py", line 560, in urlopen
    body=body, headers=headers)
  File "/usr/lib/python3/dist-packages/urllib3/connectionpool.py", line 354, in _make_request
    conn.request(method, url, **httplib_request_kw)
  File "/usr/lib/python3.5/http/client.py", line 1106, in request
    self._send_request(method, url, body, headers)
  File "/usr/lib/python3.5/http/client.py", line 1151, in _send_request
    self.endheaders(body)
  File "/usr/lib/python3.5/http/client.py", line 1102, in endheaders
    self._send_output(message_body)
  File "/usr/lib/python3.5/http/client.py", line 934, in _send_output
    self.send(msg)
  File "/usr/lib/python3.5/http/client.py", line 877, in send
    self.connect()
  File "/usr/lib/python3/dist-packages/urllib3/connection.py", line 162, in connect
    conn = self._new_conn()
  File "/usr/lib/python3/dist-packages/urllib3/connection.py", line 146, in _new_conn
    self, "Failed to establish a new connection: %s" % e)
requests.packages.urllib3.exceptions.NewConnectionError: <requests.packages.urllib3.connection.HTTPConnection object at 0x7f53e8448048>: Failed to establish a new connection: [Errno 111] Connection refused

During handling of the above exception, another exception occurred:

Traceback (most recent call last):
  File "/usr/lib/python3/dist-packages/requests/adapters.py", line 376, in send
    timeout=timeout
  File "/usr/lib/python3/dist-packages/urllib3/connectionpool.py", line 610, in urlopen
    _stacktrace=sys.exc_info()[2])
  File "/usr/lib/python3/dist-packages/urllib3/util/retry.py", line 273, in increment
    raise MaxRetryError(_pool, url, error or ResponseError(cause))
requests.packages.urllib3.exceptions.MaxRetryError: HTTPConnectionPool(host='127.0.0.1', port=8983): Max retries exceeded with url: /solr/admin/cores?action=CREATE&name=priya_test&instanceDir=priya_test&dataDir=data&configSet=template_ok (Caused by NewConnectionError('<requests.packages.urllib3.connection.HTTPConnection object at 0x7f53e8448048>: Failed to establish a new connection: [Errno 111] Connection refused',))

During handling of the above exception, another exception occurred:

Traceback (most recent call last):
  File "/home/ubuntu/project/search_engine/portal_server/webr_api/__init__.py", line 604, in create_engine
    res = requests.get(url)
  File "/usr/lib/python3/dist-packages/requests/api.py", line 67, in get
    return request('get', url, params=params, **kwargs)
  File "/usr/lib/python3/dist-packages/requests/api.py", line 53, in request
    return session.request(method=method, url=url, **kwargs)
  File "/usr/lib/python3/dist-packages/requests/sessions.py", line 480, in request
    resp = self.send(prep, **send_kwargs)
  File "/usr/lib/python3/dist-packages/requests/sessions.py", line 588, in send
    r = adapter.send(request, **kwargs)
  File "/usr/lib/python3/dist-packages/requests/adapters.py", line 437, in send
    raise ConnectionError(e, request=request)
requests.exceptions.ConnectionError: HTTPConnectionPool(host='127.0.0.1', port=8983): Max retries exceeded with url: /solr/admin/cores?action=CREATE&name=priya_test&instanceDir=priya_test&dataDir=data&configSet=template_ok (Caused by NewConnectionError('<requests.packages.urllib3.connection.HTTPConnection object at 0x7f53e8448048>: Failed to establish a new connection: [Errno 111] Connection refused',))
2019-01-14 04:08:51,886 > INFO > Starting Webserver
2019-01-14 04:09:11,860 > INFO > Starting Webserver
